2019-08-08 16:47:41,596.596Z INFO cascade.py::_setup_logger:159 9:MainThread logger initialized, log file: /mnt/batch/tasks/startup/wd/cascade.log
2019-08-08 16:47:41,597.597Z INFO cascade.py::main:1313 9:MainThread max concurrent downloads: 10
2019-08-08 16:47:41,597.597Z DEBUG cascade.py::main:1343 9:MainThread ip address: 10.0.0.4
2019-08-08 16:47:41,806.806Z DEBUG cascade.py::_direct_download_resources_async:758 9:MainThread blob lease 272eaaef-03d4-4ce9-a5dd-ebd1ef4e0555 acquired for resource singularity:busybox
2019-08-08 16:47:41,807.807Z INFO cascade.py::_pull_and_save:522 9:Thread-1 pulling singularity image busybox
2019-08-08 16:47:41,808.808Z ERROR cascade.py::write:137 9:MainThread Executing <Task pending coro=<download_monitor_async() running at cascade.py:1136> wait_for=<Future pending cb=[<TaskWakeupMethWrapper object at 0x7fdcac4f40a8>()] created at /usr/lib/python3.6/asyncio/base_events.py:295> cb=[_run_until_complete_cb() at /usr/lib/python3.6/asyncio/base_events.py:196] created at /usr/lib/python3.6/asyncio/base_events.py:463> took 0.115 seconds
2019-08-08 16:47:41,808.808Z ERROR cascade.py::flush:141 9:MainThread <__main__.StandardStreamLogger object at 0x7fdcac4c3ac8>
2019-08-08 16:47:41,822.822Z ERROR cascade.py::run:458 9:Thread-1 singularity pull failed: stdout= stderr=ERROR: pull is only supported for shub URIs
Traceback (most recent call last):
  File "cascade.py", line 456, in run
    self._pull_and_save()
  File "cascade.py", line 549, in _pull_and_save
    grtype, stdout, stderr))
RuntimeError: singularity pull failed: stdout= stderr=ERROR: pull is only supported for shub URIs

2019-08-08 16:47:41,832.832Z DEBUG cascade.py::run:478 9:Thread-1 blob lease released for singularity:busybox
2019-08-08 16:47:42,810.810Z CRITICAL cascade.py::download_monitor_async:1113 9:MainThread Thread exceptions encountered, terminating
2019-08-08 16:47:42,810.810Z ERROR cascade.py::flush:141 9:MainThread <__main__.StandardStreamLogger object at 0x7fdcac4c3ac8>
2019-08-08 16:47:42,811.811Z ERROR cascade.py::write:137 9:MainThread Traceback (most recent call last):

2019-08-08 16:47:42,811.811Z ERROR cascade.py::write:137 9:MainThread   File "cascade.py", line 1377, in <module>

2019-08-08 16:47:42,812.812Z ERROR cascade.py::write:137 9:MainThread     
2019-08-08 16:47:42,812.812Z ERROR cascade.py::write:137 9:MainThread main()
2019-08-08 16:47:42,812.812Z ERROR cascade.py::write:137 9:MainThread   File "cascade.py", line 1353, in main

2019-08-08 16:47:42,813.813Z ERROR cascade.py::write:137 9:MainThread     
2019-08-08 16:47:42,813.813Z ERROR cascade.py::write:137 9:MainThread distribute_global_resources(loop, blob_client, table_client, ipaddress)
2019-08-08 16:47:42,813.813Z ERROR cascade.py::write:137 9:MainThread   File "cascade.py", line 1285, in distribute_global_resources

2019-08-08 16:47:42,814.814Z ERROR cascade.py::write:137 9:MainThread     
2019-08-08 16:47:42,814.814Z ERROR cascade.py::write:137 9:MainThread loop, blob_client, table_client, ipaddress, nentities))
2019-08-08 16:47:42,814.814Z ERROR cascade.py::write:137 9:MainThread   File "/usr/lib/python3.6/asyncio/base_events.py", line 484, in run_until_complete

2019-08-08 16:47:42,814.814Z ERROR cascade.py::write:137 9:MainThread     
2019-08-08 16:47:42,814.814Z ERROR cascade.py::write:137 9:MainThread return future.result()
2019-08-08 16:47:42,814.814Z ERROR cascade.py::write:137 9:MainThread   File "cascade.py", line 1115, in download_monitor_async

2019-08-08 16:47:42,815.815Z ERROR cascade.py::write:137 9:MainThread     
2019-08-08 16:47:42,815.815Z ERROR cascade.py::write:137 9:MainThread raise _THREAD_EXCEPTIONS[0]
2019-08-08 16:47:42,815.815Z ERROR cascade.py::write:137 9:MainThread   File "cascade.py", line 456, in run

2019-08-08 16:47:42,816.816Z ERROR cascade.py::write:137 9:MainThread     
2019-08-08 16:47:42,816.816Z ERROR cascade.py::write:137 9:MainThread self._pull_and_save()
2019-08-08 16:47:42,816.816Z ERROR cascade.py::write:137 9:MainThread   File "cascade.py", line 549, in _pull_and_save

2019-08-08 16:47:42,816.816Z ERROR cascade.py::write:137 9:MainThread     
2019-08-08 16:47:42,817.817Z ERROR cascade.py::write:137 9:MainThread grtype, stdout, stderr))
2019-08-08 16:47:42,818.818Z ERROR cascade.py::write:137 9:MainThread RuntimeError
2019-08-08 16:47:42,818.818Z ERROR cascade.py::write:137 9:MainThread : 
2019-08-08 16:47:42,818.818Z ERROR cascade.py::write:137 9:MainThread singularity pull failed: stdout= stderr=ERROR: pull is only supported for shub URIs

2019-08-08 16:47:42,818.818Z ERROR cascade.py::flush:141 9:MainThread <__main__.StandardStreamLogger object at 0x7fdcac4c3ac8>
2019-08-08 16:47:42,818.818Z ERROR cascade.py::flush:141 9:MainThread <__main__.StandardStreamLogger object at 0x7fdcac4c3ac8>
